Workbook

Sheet Global IP Scan Kanban Board
C24: In Progress (WIP Limits)
B25: Local Coordinator | C25: Preperation | D25: Baseline ID | E25: Incremental ID | F25: Communication | G25: Total
A26: GTLC China | B26: Amy | C26: 1 | D26: 1 | E26: 5 | F26: 1 | G26: =SUM(C26:F26) -> 8
A27: GTLC India | B27: Komal | C27: 5 | D27: 2 | E27: 8 | F27: 4 | G27: =SUM(C27:F27) -> 19
A28: GTLC Germany | B28: Klaus | C28: 1 | D28: 1 | E28: 2 | F28: 2 | G28: =SUM(C28:F28) -> 6
A29: GTLC Canada | B29: Raj | C29: 5 | D29: 5 | E29: 10 | F29: 5 | G29: =SUM(C29:F29) -> 25
A31: **The above table shows the WIP Limits ONLY. To find out the WIP for a site, refer to the Local Kanban Board**

Sheet Data
B1: In Progress | C1: Done
A2: China | B2: =COUNTIFS(#REF!,"GTLC China",#REF!,"In Progress") -> #REF! | C2: =COUNTIFS(#REF!,"GTLC China",#REF!,"Done") -> #REF!
A3: India | B3: =COUNTIFS(#REF!,"GTLC India",#REF!,"In Progress") -> #REF! | C3: =COUNTIFS(#REF!,"GTLC India",#REF!,"Done") -> #REF!
A4: Germany | B4: =COUNTIFS(#REF!,"GTLC Germany",#REF!,"In Progress") -> #REF! | C4: =COUNTIFS(#REF!,"GTLC Germany",#REF!,"Done") -> #REF!
A5: Canada | B5: =COUNTIFS(#REF!,"GTLC Canada",#REF!,"In Progress") -> #REF! | C5: =COUNTIFS(#REF!,"GTLC Canada",#REF!,"Done") -> #REF!
A6: Global | B6: =SUM(B2:B5) -> #REF! | C6: =SUM(C2:C5) -> #REF!
A9: Backlog
A10: P1 | B10: =COUNTIFS(#REF!,"GLOBAL",#REF!,"P1",#REF!,"backlog") -> #REF!
A11: P2 | B11: =COUNTIFS(#REF!,"GLOBAL",#REF!,"P2",#REF!,"backlog") -> #REF!
A12: P3 | B12: =COUNTIFS(#REF!,"GLOBAL",#REF!,"P3",#REF!,"backlog") -> #REF!
A13: Total | B13: =SUM(B10:B12) -> #REF!
A15: RTC Passed
A16: P1 | B16: =COUNTIFS(#REF!,"RTC Passed",#REF!,"P1") -> #REF!
A17: P2 | B17: =COUNTIFS(#REF!,"RTC Passed",#REF!,"P2") -> #REF!
A18: Total | B18: =SUM(B16:B17) -> #REF!

Sheet Data Validation
A1: Values for Data Validation (do not edit) | B1: Program Category | C1: Delivery Mode | D1: Priority | E1: Severity | F1: Previously Scanned | G1: Scan Category | H1: Location | I1: FOSS Analyst | J1: Owner I-Number mapping | K1: FOSS Scan State | L1: Black Duck Scan | M1: Ticket Tracking Status | N1: Commercial Analyst | O1: Commercial Scan State | P1: Web Service Analyst | Q1: Web Service Scan State | R1: Continuous Scan | S1: L1 Manager | T1: L1 Development Unit | U1: Board Area Member | V1: Board Area
B2: Docker Container | C2: On-Demand (SaaS) | D2: P1 | E2: S1 | F2: Y | G2: Incremental ONLY | H2: GLOBAL | I2: Global | J2: Global | K2: Backlog | L2: Y | M2: Open | N2: Komal | O2: Backlog | P2: Yi Zhang | Q2: Backlog | R2: Y | S2: Fei Yu Xu | T2: Artificial Intelligence | U2: Juergen Mueller | V2: Technology and Innovation
B3: Source Code | C3: On-Premise | D3: P2 | E3: S2 | F3: N | G3: OneTime Scan | H3: GTLC China | I3: Prashant | J3: I536654 | K3: Cancelled | M3: Closed | N3: Yi Zhang | O3: In Progress | P3: Raksha | Q3: In Progress | R3: N | S3: Manoj Swaminathan | T3: ISBN CloudOps Cross COPS
B4: On-Premise | C4: On-Mobile Device | D4: P3 | E4: S3 | H4: GTLC India | I4: RTC Passed | J4: RTC Passed | K4: In Progress | N4: Raksha | O4: Done | P4: Yash | Q4: Done | S4: Muhammad Alam | T4: ISBN Executive
B5: On-Mobile Device | E5: S4 | H5: GTLC Germany | I5: Amy | J5: I076757 | K5: Done | N5: ChangFei | O5: N/A | P5: Komal | Q5: N/A | S5: Florian Heretsch | T5: PE MXE Mgmt
B6: ATS | H6: GTLC Canada | I6: Arshia | J6: I557608 | K6: RTC Passed | L6: N | N6: Yi Zhang | S6: Gary Slater | T6: Global Cloud Services
B7: Custom Code | H7: GTLC Vietnam | I7: Jessie | J7: I300127 | N7: Yash | S7: Michael Paul Weingartner | T7: SAP BTP Core
B8: On-Demand (SaaS) | H8: RTC Passed | I8: Sarah | J8: I076758 | N8: Raksha | S8: Juergen Kreuziger | T8: SAP HANA Database & Analytics
B9: Outbound OSS | I9: Tina | J9: I076782 | N9: Sarah Li | S9: Sonja Lienard | T9: BTP ABAP Platform Mgmt (SE)
B10: Outbound OEM | I10: Deb | J10: I077275 | N10: Tina Liao | S10: Andrea Fluegel | T10: BTP Core AP Mgmt & COO SE
I11: Alekh | J11: I556028 | N11: N/A | S11: Sina Doebbelin | T11: T&I Board Office
I12: Komal | J12: I321911 | S12: Bhagat Nainani | T12: BTP Core AP Mgmt & COO (US)
I13: Gunter | J13: D038475 | S13: Michael Ameling | T13: Cross Architecture
I14: Klaus | J14: D061043 | S14: Harald Kuck | T14: TI ABAP Platform Mgmt (SE)
I15: Shweta | J15: D059874 | S15: Martin Heinig | T15: New Ventures & Technologies
I16: Brian | J16: I844758 | S16: Irfan Khan | T16: SAP HANA Database & Analytics
I17: Devan | J17: I819681 | S17: Anja Schneider | T17: T&I COO
I18: Erika | J18: I828891 | S18: Meg bear | T18: People | U18: Thomas Saueressig | V18: SAP Product Engineering
I19: Hamad | J19: I831094 | S19: Andreas Heckman | T19: Customer Solution Support and Innovation
I20: Jimmy | J20: I819510 | S20: Peter Pluim | T20: Enterprise Cloud Services
I21: Justine | J21: I822712 | S21: Jan Gilg | T21: SAP S/4 HANA
I22: Matthew | J22: I844765 | S22: Julia Lakatos | T22: SAP Product Engineering Office
I23: Mitch | J23: I830949 | S23: John Wookey | T23: Intelling Spend and Business Network
I24: Siva | J24: I537790 | S24: Bob Stutz | T24: Customer Experience E&O
I25: Sabrina | J25: I822781 | S25: Eva Zauke | T25: SAP Enterprise Adoption
I26: Tes | J26: I830866 | S26: Stefan Stainle | T26: COO & Strategy, SAP Product Engineering
I27: Rajat | J27: I501689 | S27: Philipp Herzig | T27: Product Engineering Intelligent Enterprise and Cross Architecture
I28: Assmitra | J28: I342117 | S28: Jurgen Sattler | T28: One Strike
I29: Ravi | J29: D072009 | S29: Benedikt Lehnert | T29: SAP Design
I30: Gaurisha | J30: I748895 | S30: Dragana Bjelonic | T30: Chief Controlling Ofiicer
... I33: Madhusudanan | J33: I503416 | S33: Christiane Kubach | T33: Executive Comms & Events
I34: Giang | J34: I540507 | S34: Mira Wohlhueter | T34: Executive Comms & Events | U34: Scott Russell | V34: Customer Success
I35: Domenik | J35: I500407 | S35: Eric Stine | T35: Chief of Staff, Customer Success
I36: Raksha | J36: I353860 | S36: Greg Tomb | T36: Solution Area Sales
I37: Yash | J37: I537966 | S37: Steve Shute | T37: Chief Operation Officers, Customer Success
I38: Shivani | J38: I537015 | S38: Thomas Pfiester | T38: CS&D Regions Mgmt MENA
I39: Alekh | J39: I556028 | S39: Thomas Bamberger | T39: Customer Engagement & Experience
I40: Mariem | J40: I556456 | S40: Ken Hamel | T40: Business Operations, Customer Success
I41: Harshal | J41: I557311 | S41: Holger Lemanczyk | T41: Strategy & Transformation, Customer Success
I42: Liye | J42: I853975 | S42: John Graham | T42: Strategy & Transformation, Customer Success
...

Sheet Sheet1
A3: TripIt Mobile iOS | B3: Don
A4: TripIt Mobile Android | B4: done
A5: Complete android
A6: complete ios
A7: SAP Concur Mobile iOS | B7: done
A8: SAP Concur Mobile Android | B8: done
A9: SAP Concur Mobile Tencent H1 2026
A13: Philipp Herzig | B13: =VLOOKUP(A13,'Data Validation'!S:T,2,FALSE) -> Product Engineering Intelligent Enterprise and Cross Architecture | C13: Venkatesan, Divya<divya.venkatesan@sap.com | D13: On-Premise | E13: On-Premise | F13: P2 | G13: S2 | H13: Y | I13: Incremental ONLY | J13: FS on K8s Delivery 2609a | K13: 46244 | L13: 46255 | M13: 46268 | AA13: 500000 | AB13: Open | AC13: No | AD13: =IF((AND((AS13-TODAY())<=30,(L13-TODAY())<=0,(F27="P1")))=TRUE,"Yes",IF(AND((AS13-TODAY())<=30,(L13-TODAY())<=0,(F27="P2"))=TRUE,"Yes","No")) -> No | AE13: I758929 | AF13: 21.449057 | AG13: 1.509434 | AH13: =SUM($AG$2:AG13) -> 1.509434 | AI13: 17.449057 | AJ13: 21.449057 | AK13: 46253 | AL13: N | AM13: Y | AN13: =AS13-S13 -> 46267 | AR13: -1 | AS13: 46267

Sheet Active Scans
A1: L1 Manager | B1: L1 Development Unit | C1: Dev Contact | D1: Program Category | E1: Delivery Mode | F1: Priority | G1: Severity | H1: Previously Scanned | I1: Scan Category | J1: Program (Delivery) | K1: Start of Development | L1: End of Development | M1: RTC | N1: Location | O1: FOSS Analyst | P1: FOSS Scan State | Q1: Black Duck Scan | R1: FOSS Scan Assigned | S1: FOSS Scan Closed | T1: Commercial Scan Status | U1: Comm Analyst | V1: CTP Scan Ticket JIRA link | W1: Web Service Scan Status | X1: Web Service Analyst | Y1: WS Scan Ticket JIRA link | Z1: Comments | AA1: SLOC Count | AB1: Tracking System Ticket Status | AC1: RTC Passed | AD1: Recommended to Request Exemption | AE1: Owner # | AF1: Estimated Calendar Week (CW) for the scan to be "In Progress" | AG1: Estimated # of days to complete the first round of scan | AH1: Cumulative Days | AI1: CW to be added to the current CW | AJ1: Estimated CW for scan to be in progress | AK1: Scan Submission Date | AL1: Continuous scan | AM1: Crown Jewel | AN1: Closed within SLA | AO1: Unreviewed components | AP1: Unmatched | AQ1: Snippets | AS1: RDM | AT1: Maintenance
A2: Uma Rani T M | B2: Strategy & Transformation, Customer Success | C2: MEGEVAND,Emmanuel<emmanuel.megevand@sap.com> | D2: Outbound OEM | E2: On-Premise | F2: P1 | G2: S2 | H2: Y | I2: Incremental ONLY | J2: SAP Information Steward 4.3 SP03 | K2: N/A | L2: 46364 | M2: 46387 | N2: GLOBAL | O2: Global | P2: Backlog | Q2: Y | AA2: 500000 | AB2: Open | AC2: No | AD2: Yes | AE2: I762314 | AF2: 8.1962264 | AG2: 1.509434 | AH2: 209.81132 | AI2: 4.1962264 | AJ2: 8.1962264 | AK2: 46154 | AL2: N | AM2: N | AN2: 0 | AS2: 46387
A3: Stefan Steinle | B3: =VLOOKUP(A3,'Data Validation'!S:T,2,FALSE) -> Customer Solution Support and Innovation | C3: Kabadzhova, Kremena <kremena.kabadzhova@sap.com> | D3: Source Code | E3: On-Premise | F3: P2 | G3: S1 | H3: Y | I3: Incremental ONLY | J3: SAP Cloud Appliance Library 4.60 | K3: N/A | L3: 46282 | M3: 46294 | N3: GTLC India | O3: Apoorva | P3: Done | Q3: Y | R3: 46283 | S3: 46293 | AA3: 500000 | AB3: Open | AC3: No | AD3: =IF((AND((AS3-TODAY())<=30,(L3-TODAY())<=0,(F4="P1")))=TRUE,"Yes",IF(AND((AS3-TODAY())<=30,(L3-TODAY())<=0,(F4="P2"))=TRUE,"Yes","No")) -> Yes | AE3: =VLOOKUP(O3,'Data Validation'!I:J,2,FALSE) -> C5367590 | AF3: =IF(AJ3<=53,AJ3,AJ3-52) -> 41.060377 | AG3: =IF(H3="Y",(((160/1000000)*AA3)/5.3)*0.1,((160/1000000)*AA3)/5.3) -> 1.509434 | AH3: =SUM($AG$2:AG3) -> 3.0188679 | AI3: =AH3/50 -> 0.060377358 | AJ3: =WEEKNUM(TODAY())+AI3 -> 41.060377 | AK3: 46006 | AL3: Y | AM3: N | AN3: =AS3-S3 -> 3 | AS3: 46296
A4: Stefan Steinle | B4: =VLOOKUP(A4,'Data Validation'!S:T,2,FALSE) -> Customer Solution Support and Innovation | C4: Kabadzhova, Kremena <kremena.kabadzhova@sap.com> | D4: Source Code | E4: On-Premise | F4: P2 | G4: S1 | H4: Y | I4: Incremental ONLY | J4: SAP Cloud Appliance Library 4.61 | K4: N/A | L4: 46310 | M4: 46322 | N4: GLOBAL | O4: Global | P4: Backlog | Q4: Y | AA4: 500000 | AB4: Open | AC4: No | AD4: =IF((AND((AS4-TODAY())<=30,(L4-TODAY())<=0,(F5="P1")))=TRUE,"Yes",IF(AND((AS4-TODAY())<=30,(L4-TODAY())<=0,(F5="P2"))=TRUE,"Yes","No")) -> No | AE4: =VLOOKUP(O4,'Data Validation'!I:J,2,FALSE) -> Global | AF4: =IF(AJ4<=53,AJ4,AJ4-52) -> 41.090566 | AG4: =IF(H4="Y",(((160/1000000)*AA4)/5.3)*0.1,((160/1000000)*AA4)/5.3) -> 1.509434 | AH4: =SUM($AG$2:AG4) -> 4.5283019 | AI4: =AH4/50 -> 0.090566038 | AJ4: =WEEKNUM(TODAY())+AI4 -> 41.090566 | AK4: 46006 | AL4: Y | AM4: N | AN4: =AS4-S4 -> 46324 | AS4: 46324
A5: Stefan Steinle | B5: =VLOOKUP(A5,'Data Validation'!S:T,2,FALSE) -> Customer Solution Support and Innovation | C5: Kabadzhova, Kremena <kremena.kabadzhova@sap.com> | D5: Source Code | E5: On-Premise | F5: P2 | G5: S1 | H5: Y | I5: Incremental ONLY | J5: SAP Cloud Appliance Library 4.62 | K5: N/A | L5: 46338 | M5: 46350 | N5: GLOBAL | O5: Global | P5: Backlog | Q5: Y | AA5: 500000 | AB5: Open | AC5: No | AD5: =IF((AND((AS5-TODAY())<=30,(L5-TODAY())<=0,(F6="P1")))=TRUE,"Yes",IF(AND((AS5-TODAY())<=30,(L5-TODAY())<=0,(F6="P2"))=TRUE,"Yes","No")) -> No | AE5: =VLOOKUP(O5,'Data Validation'!I:J,2,FALSE) -> Global | AF5: =IF(AJ5<=53,AJ5,AJ5-52) -> 41.120755 | AG5: =IF(H5="Y",(((160/1000000)*AA5)/5.3)*0.1,((160/1000000)*AA5)/5.3) -> 1.509434 | AH5: =SUM($AG$2:AG5) -> 6.0377358 | AI5: =AH5/50 -> 0.12075472 | AJ5: =WEEKNUM(TODAY())+AI5 -> 41.120755 | AK5: 46006 | AL5: Y | AM5: N | AN5: =AS5-S5 -> 46352 | AS5: 46352
A6: Stefan Steinle | B6: =VLOOKUP(A6,'Data Validation'!S:T,2,FALSE) -> Customer Solution Support and Innovation | C6: Kabadzhova, Kremena <kremena.kabadzhova@sap.com> | D6: Source Code | E6: On-Premise | F6: P2 | G6: S1 | H6: Y | I6: Incremental ONLY | J6: SAP Cloud Appliance Library 4.63 | K6: N/A | L6: 46394 | M6: 46406 | N6: GLOBAL | O6: Global | P6: Backlog | Q6: Y | AA6: 500000 | AB6: Open | AC6: No | AD6: No | AE6: =VLOOKUP(O6,'Data Validation'!I:J,2,FALSE) -> Global | AF6: =IF(AJ6<=53,AJ6,AJ6-52) -> 41.150943 | AG6: =IF(H6="Y",(((160/1000000)*AA6)/5.3)*0.1,((160/1000000)*AA6)/5.3) -> 1.509434 | AH6: =SUM($AG$2:AG6) -> 7.5471698 | AI6: =AH6/50 -> 0.1509434 | AJ6: =WEEKNUM(TODAY())+AI6 -> 41.150943 | AK6: 46006 | AL6: Y | AM6: N | AN6: =AS6-S6 -> 46408 | AS6: 46408
A7: Michael Ameling | B7: =VLOOKUP(A7,'Data Validation'!S:T,2,FALSE) -> Cross Architecture | C7: Yadav, Prashant<prashant.yadav03@sap.com> | D7: On-Mobile Device | E7: On-Mobile Device | F7: P2 | G7: S2 | H7: Y | I7: Incremental ONLY | J7: TripIt Mobile Android 09/2026 | K7: N/A | L7: 46268 | M7: 46283 | N7: GTLC India | O7: Sharath | P7: Done | Q7: Y | R7: 46280 | S7: 46282 | AA7: 500000 | AB7: Open | AC7: No | AD7: =IF((AND((AS7-TODAY())<=30,(L7-TODAY())<=0,(F7="P1")))=TRUE,"Yes",IF(AND((AS7-TODAY())<=30,(L7-TODAY())<=0,(F7="P2"))=TRUE,"Yes","No")) -> Yes | AE7: =VLOOKUP(O7,'Data Validation'!I:J,2,FALSE) -> C5385258 | AF7: =IF(AJ7<=53,AJ7,AJ7-52) -> 2.1622642 | AG7: =IF(H7="Y",(((160/1000000)*AA7)/5.3)*0.1,((160/1000000)*AA7)/5.3) -> 1.509434 | AH7: =SUM($AG$2:AG212) -> 658.11321 | AI7: =AH7/50 -> 13.162264 | AJ7: =WEEKNUM(TODAY())+AI7 -> 54.162264 | AK7: 46049 | AL7: Y | AM7: Y | AN7: =AS7-S7 -> -10 | AS7: 46272
A8: Michael Ameling | B8: =VLOOKUP(A8,'Data Validation'!S:T,2,FALSE) -> Cross Architecture | C8: Yadav, Prashant<prashant.yadav03@sap.com> | D8: On-Mobile Device | E8: On-Mobile Device | F8: P2 | G8: S2 | H8: Y | I8: Incremental ONLY | J8: TripIt Mobile iOS 09/2026 | K8: N/A | L8: 46268 | M8: 46283 | N8: GTLC India | O8: Sharath | P8: Done | Q8: Y | R8: 46280 | S8: 46282 | AA8: 500000 | AB8: Open | AC8: No | AD8: =IF((AND((AS8-TODAY())<=30,(L8-TODAY())<=0,(F8="P1")))=TRUE,"Yes",IF(AND((AS8-TODAY())<=30,(L8-TODAY())<=0,(F8="P2"))=TRUE,"Yes","No")) -> Yes | AE8: =VLOOKUP(O8,'Data Validation'!I:J,2,FALSE) -> C5385258 | AF8: =IF(AJ8<=53,AJ8,AJ8-52) -> 2.1924528 | AG8: =IF(H8="Y",(((160/1000000)*AA8)/5.3)*0.1,((160/1000000)*AA8)/5.3) -> 1.509434 | AH8: =SUM($AG$2:AG213) -> 659.62264 | AI8: =AH8/50 -> 13.192453 | AJ8: =WEEKNUM(TODAY())+AI8 -> 54.192453 | AK8: 46049 | AL8: Y | AM8: Y | AN8: =AS8-S8 -> -10 | AS8: 46272
A9: Peter Pluim | B9: Enterprise Cloud Services | C9: Yonchev, Tsonyo<tsonyo.yonchev@sap.com> | D9: On-Premise | E9: On-Premise | F9: P2 | G9: S2 | H9: Y | I9: Incremental ONLY | J9: LaMaRT 2026.17 | K9: 46117 | L9: 46262 | M9: 46279 | N9: GTLC Germany | O9: Sushma | P9: In Progress | Q9: Y | R9: 46268 | AA9: 500000 | AB9: Open | AC9: No | AD9: =IF((AND((AS9-TODAY())<=30,(L10-TODAY())<=0,(F9="P1")))=TRUE,"Yes",IF(AND((AS9-TODAY())<=30,(L10-TODAY())<=0,(F9="P2"))=TRUE,"Yes","No")) -> Yes | AE9: =VLOOKUP(O9,'Data Validation'!I:J,2,FALSE) -> I773708 | AF9: =IF(AJ9<=53,AJ9,AJ9-52) -> 43.05283 | AG9: =IF(H9="Y",(((160/1000000)*AA9)/5.3)*0.1,((160/1000000)*AA9)/5.3) -> 1.509434 | AH9: =SUM($AG$2:AG51) -> 102.64151 | AI9: =AH9/50 -> 2.0528302 | AJ9: =WEEKNUM(TODAY())+AI9 -> 43.05283 | AK9: 46140 | AL9: Y | AM9: N | AN9: =AS9-S9 -> 46279 | AS9: 46279
A10: Michael Ameling | B10: =VLOOKUP(A10,'Data Validation'!S:T,2,FALSE) -> Cross Architecture | C10: Yadav, Prashant<prashant.yadav03@sap.com> | D10: On-Mobile Device | E10: On-Mobile Device | F10: P2 | G10: S2 | H10: Y | I10: Incremental ONLY | J10: SAP Concur Mobile iOS H1 2026 - Sep | K10: N/A | L10: 46279 | M10: 46286 | N10: GTLC India | O10: Sharath | P10: Done | Q10: Y | R10: 46280 | S10: 46282 | AA10: 500000 | AB10: Open | AC10: No | AD10: =IF((AND((AS10-TODAY())<=30,(L10-TODAY())<=0,(F59="P1")))=TRUE,"Yes",IF(AND((AS10-TODAY())<=30,(L10-TODAY())<=0,(F59="P2"))=TRUE,"Yes","No")) -> Yes | AE10: =VLOOKUP(O10,'Data Validation'!I:J,2,FALSE) -> C5385258 | AF10: =IF(AJ10<=53,AJ10,AJ10-52) -> 41.271698 | AG10: =IF(H10="Y",(((160/1000000)*AA10)/5.3)*0.1,((160/1000000)*AA10)/5.3) -> 1.509434 | AH10: =SUM($AG$2:AG10) -> 13.584906 | AI10: =AH10/50 -> 0.27169811 | AJ10: =WEEKNUM(TODAY())+AI10 -> 41.271698 | AK10: 46182 | AL10: Y | AM10: Y | AN10: =AS10-S10 -> 4 | AS10: 46286
A11: Michael Ameling | B11: =VLOOKUP(A11,'Data Validation'!S:T,2,FALSE) -> Cross Architecture | C11: Yadav, Prashant<prashant.yadav03@sap.com> | D11: On-Mobile Device | E11: On-Mobile Device | F11: P2 | G11: S2 | H11: Y | I11: Incremental ONLY | J11: SAP Concur Mobile Android H1 2026 - Sep | K11: N/A | L11: 46279 | M11: 46286 | N11: GTLC India | O11: Sharath | P11: Done | Q11: Y | R11: 46280 | S11: 46282 | AA11: 500000 | AB11: Open | AC11: No | AD11: =IF((AND((AS11-TODAY())<=30,(L11-TODAY())<=0,(F60="P1")))=TRUE,"Yes",IF(AND((AS11-TODAY())<=30,(L11-TODAY())<=0,(F60="P2"))=TRUE,"Yes","No")) -> Yes | AE11: =VLOOKUP(O11,'Data Validation'!I:J,2,FALSE) -> C5385258 | AF11: =IF(AJ11<=53,AJ11,AJ11-52) -> 41.301887 | AG11: =IF(H11="Y",(((160/1000000)*AA11)/5.3)*0.1,((160/1000000)*AA11)/5.3) -> 1.509434 | AH11: =SUM($AG$2:AG11) -> 15.09434 | AI11: =AH11/50 -> 0.30188679 | AJ11: =WEEKNUM(TODAY())+AI11 -> 41.301887 | AK11: 46182 | AL11: Y | AM11: Y | AN11: =AS11-S11 -> 4 | AS11: 46286
A12: Dominik Metzger | B12: People Growth Management Office UK | C12: Reichenbach, Zsolt<zsolt.reichenbach@sap.com> | D12: On-Premise | E12: On-Premise | F12: P2 | G12: S2 | H12: Y | I12: Incremental ONLY | J12: IBP 2611 - Beta Release | K12: 46168 | L12: 46255 | M12: 46286 | N12: GTLC Germany | O12: Giang | P12: In Progress | Q12: Y | R12: 46268 | AA12: 500000 | AB12: Open | AC12: No | AD12: Yes | AE12: I541859 | AF12: 22.29434 | AG12: 1.509434 | AH12: 914.71699 | AI12: 18.29434 | AJ12: 22.29434 | AK12: 46260 | AL12: N | AM12: N | AN12: -13 | AS12: 46274
A13: Stefan Steinle | B13: Customer Solution Support and Innovation | C13: Andreev, Ivan <ivan.andreev02@sap.com> | D13: On-Premise | E13: On-Premise | F13: P2 | G13: S2 | H13: Y | I13: Incremental ONLY | J13: SL Toolset for Cloud 2605Bb(T2026.27) | K13: N/A | L13: 46272 | M13: 46287 | N13: GTLC India | O13: Arpitha | P13: Done | Q13: Y | R13: 46273 | S13: 46276 | AA13: 500000 | AB13: Open | AC13: No | AD13: =IF((AND((AS13-TODAY())<=30,(L13-TODAY())<=0,(F14="P1")))=TRUE,"Yes",IF(AND((AS13-TODAY())<=30,(L13-TODAY())<=0,(F14="P2"))=TRUE,"Yes","No")) -> Yes | AE13: C5367590 | AF13: 22.415094 | AG13: 1.509434 | AH13: =SUM($AG$2:AG13) -> 18.113208 | AI13: 18.415094 | AJ13: 22.415094 | AK13: 46128 | AL13: Y | AM13: N | AN13: =AS13-S13 -> 11 | AS13: 46287
A14: Philipp Herzig | B14: =VLOOKUP(A14,'Data Validation'!S:T,2,FALSE) -> Product Engineering Intelligent Enterprise and Cross Architecture | C14: Mueller, Christian Mathias <christ.mueller@sap.com> | D14: Source Code | E14: On-Mobile Device | F14: P2 | G14: S2 | H14: Y | I14: Incremental ONLY | J14: AI Libraries and SDKs MDG 25 2609a | K14: N/A | L14: 46279 | M14: 46288 | N14: GLOBAL | O14: Global | P14: Cancelled | Q14: Y | Z14: No longer delivered | AA14: 500000 | AB14: Open | AC14: No | AD14: =IF((AND((AS14-TODAY())<=30,(L14-TODAY())<=0,(F14="P1")))=TRUE,"Yes",IF(AND((AS14-TODAY())<=30,(L14-TODAY())<=0,(F14="P2"))=TRUE,"Yes","No")) -> Yes | AE14: =VLOOKUP(O14,'Data Validation'!I:J,2,FALSE) -> Global | AF14: =IF(AJ14<=53,AJ14,AJ14-52) -> 49.392453 | AG14: =IF(H14="Y",(((160/1000000)*AA14)/5.3)*0.1,((160/1000000)*AA14)/5.3) -> 1.509434 | AH14: =SUM($AG$2:AG117) -> 419.62264 | AI14: =AH14/50 -> 8.3924528 | AJ14: =WEEKNUM(TODAY())+AI14 -> 49.392453 | AK14: 46029 | AL14: Y | AM14: N | AN14: =AS14-S14 -> 46288 | AS14: 46288
A15: Peter Pluim | B15: Enterprise Cloud Services | C15: Yonchev, Tsonyo<tsonyo.yonchev@sap.com> | D15: On-Premise | E15: On-Premise | F15: P2 | G15: S2 | H15: Y | I15: Incremental ONLY | J15: LaMaRT 2026.18 | K15: 46117 | L15: 46276 | M15: 46293 | N15: GTLC Germany | O15: Sushma | P15: In Progress | Q15: Y | R15: 46283 | AA15: 500000 | AB15: Open | AC15: No | AD15: =IF((AND((AS15-TODAY())<=30,(L16-TODAY())<=0,(F15="P1")))=TRUE,"Yes",IF(AND((AS15-TODAY())<=30,(L16-TODAY())<=0,(F15="P2"))=TRUE,"Yes","No")) -> Yes | AE15: =VLOOKUP(O15,'Data Validation'!I:J,2,FALSE) -> I773708 | AF15: =IF(AJ15<=53,AJ15,AJ15-52) -> 44.049057 | AG15: =IF(H15="Y",(((160/1000000)*AA15)/5.3)*0.1,((160/1000000)*AA15)/5.3) -> 1.509434 | AH15: =SUM($AG$2:AG57) -> 152.45283 | AI15: =AH15/50 -> 3.0490566 | AJ15: =WEEKNUM(TODAY())+AI15 -> 44.049057 | AK15: 46140 | AL15: Y | AM15: N | AN15: =AS15-S15 -> 46293 | AS15: 46293
A16: Peter Pluim | B16: =VLOOKUP(A16,'Data Validation'!S:T,2,FALSE) -> Enterprise Cloud Services | C16: Chakalova, Stela<stela.chakalova@sap.com> | D16: On-Premise | E16: On-Premise | F16: P2 | G16: S2 | H16: Y | I16: Incremental ONLY | J16: Edge Lifecycle Management 1.64 | K16: N/A | L16: 46269 | M16: 46297 | N16: GTLC India | O16: Viswa | P16: Done | Q16: Y | R16: 46269 | S16: 46280 | AA16: 500000 | AB16: Open | AC16: No | AD16: =IF((AND((AS16-TODAY())<=30,(L16-TODAY())<=0,(F17="P1")))=TRUE,"Yes",IF(AND((AS16-TODAY())<=30,(L16-TODAY())<=0,(F17="P2"))=TRUE,"Yes","No")) -> Yes | AE16: =VLOOKUP(O16,'Data Validation'!I:J,2,FALSE) -> C5366020 | AF16: 22.173585 | AG16: 1.509434 | AH16: =SUM($AG$2:AG16) -> 22.641509 | AI16: 18.173585 | AJ16: 22.173585 | AK16: 46045 | AL16: Y | AM16: N | AN16: -15 | AS16: 46297
A17: Peter Pluim | B17: Enterprise Cloud Services | C17: Yonchev, Tsonyo<tsonyo.yonchev@sap.com> | D17: On-Premise | E17: On-Premise | F17: P2 | G17: S2 | H17: Y | I17: Incremental ONLY | J17: LaMaRT 2026.19 | K17: 46117 | L17: 46290 | M17: 46307 | N17: GTLC India | O17: Apoorva | P17: In Progress | Q17: Y | R17: 46301 | AA17: 500000 | AB17: Open | AC17: No | AD17: =IF((AND((AS17-TODAY())<=30,(L18-TODAY())<=0,(F17="P1")))=TRUE,"Yes",IF(AND((AS17-TODAY())<=30,(L18-TODAY())<=0,(F17="P2"))=TRUE,"Yes","No")) -> Yes | AE17: =VLOOKUP(O17,'Data Validation'!I:J,2,FALSE) -> C5367590 | AF17: =IF(AJ17<=53,AJ17,AJ17-52) -> 44.109434 | AG17: =IF(H17="Y",(((160/1000000)*AA17)/5.3)*0.1,((160/1000000)*AA17)/5.3) -> 1.509434 | AH17: =SUM($AG$2:AG59) -> 155.4717 | AI17: =AH17/50 -> 3.109434 | AJ17: =WEEKNUM(TODAY())+AI17 -> 44.109434 | AK17: 46140 | AL17: Y | AM17: N | AN17: =AS17-S17 -> 46307 | AS17: 46307
A18: Michael Ameling | B18: =VLOOKUP(A18,'Data Validation'!S:T,2,FALSE) -> Cross Architecture | C18: Singh, Shubham<shubham.singh04@sap.com> | D18: On-Premise | E18: On-Premise | F18: P2 | G18: S2 | H18: Y | I18: Incremental ONLY | J18: APIM_EDGE_IC_2609 | K18: N/A | L18: 46283 | M18: 46311 | N18: GTLC India | O18: Soumya Pawar | P18: Done | Q18: Y | R18: 46283 | S18: 46293 | AA18: 500000 | AB18: Open | AC18: No | AD18: =IF((AND((AS18-TODAY())<=30,(L18-TODAY())<=0,(F20="P1")))=TRUE,"Yes",IF(AND((AS18-TODAY())<=30,(L18-TODAY())<=0,(F20="P2"))=TRUE,"Yes","No")) -> Yes | AE18: =VLOOKUP(O18,'Data Validation'!I:J,2,FALSE) -> C5385243 | AF18: =IF(AJ18<=53,AJ18,AJ18-52) -> 41.513208 | AG18: =IF(H18="Y",(((160/1000000)*AA18)/5.3)*0.1,((160/1000000)*AA18)/5.3) -> 1.509434 | AH18: =SUM($AG$2:AG18) -> 25.660377 | AI18: =AH18/50 -> 0.51320755 | AJ18: =WEEKNUM(TODAY())+AI18 -> 41.513208 | AK18: 46122 | AL18: Y | AM18: N | AN18: =AS18-S18 -> 18 | AS18: 46311
A19: Michael Ameling | B19: =VLOOKUP(A19,'Data Validation'!S:T,2,FALSE) -> Cross Architecture | C19: Yadav, Prashant<prashant.yadav03@sap.com> | D19: On-Mobile Device | E19: On-Mobile Device | F19: P2 | G19: S2 | H19: Y | I19: Incremental ONLY | J19: SAP Concur Mobile iOS H1 2026 - Oct | K19: N/A | L19: 46303 | M19: 46311 | N19: GLOBAL | O19: Global | P19: Backlog | Q19: Y | AA19: 500000 | AB19: Open | AC19: No | AD19: =IF((AND((AS19-TODAY())<=30,(L19-TODAY())<=0,(#REF!="P1")))=TRUE,"Yes",IF(AND((AS19-TODAY())<=30,(L19-TODAY())<=0,(#REF!="P2"))=TRUE,"Yes","No")) -> #REF! | AE19: =VLOOKUP(O19,'Data Validation'!I:J,2,FALSE) -> Global | AF19: =IF(AJ19<=53,AJ19,AJ19-52) -> 41.543396 | AG19: =IF(H19="Y",(((160/1000000)*AA19)/5.3)*0.1,((160/1000000)*AA19)/5.3) -> 1.509434 | AH19: =SUM($AG$2:AG19) -> 27.169811 | AI19: =AH19/50 -> 0.54339623 | AJ19: =WEEKNUM(TODAY())+AI19 -> 41.543396 | AK19: 46182 | AL19: Y | AM19: Y | AN19: =AS19-S19 -> 46311 | AS19: 46311
A20: Michael Ameling | B20: =VLOOKUP(A20,'Data Validation'!S:T,2,FALSE) -> Cross Architecture | C20: Yadav, Prashant<prashant.yadav03@sap.com> | D20: On-Mobile Device | E20: On-Mobile Device | F20: P2 | G20: S2 | H20: Y | I20: Incremental ONLY | J20: SAP Concur Mobile Android H1 2026 - Oct | K20: N/A | L20: 46303 | M20: 46311 | N20: GLOBAL | O20: Global | P20: Backlog | Q20: Y | AA20: 500000 | AB20: Open | AC20: No | AD20: =IF((AND((AS20-TODAY())<=30,(L20-TODAY())<=0,(F68="P1")))=TRUE,"Yes",IF(AND((AS20-TODAY())<=30,(L20-TODAY())<=0,(F68="P2"))=TRUE,"Yes","No")) -> No | AE20: =VLOOKUP(O20,'Data Validation'!I:J,2,FALSE) -> Global | AF20: =IF(AJ20<=53,AJ20,AJ20-52) -> 41.573585 | AG20: =IF(H20="Y",(((160/1000000)*AA20)/5.3)*0.1,((160/1000000)*AA20)/5.3) -> 1.509434 | AH20: =SUM($AG$2:AG20) -> 28.679245 | AI20: =AH20/50 -> 0.57358491 | AJ20: =WEEKNUM(TODAY())+AI20 -> 41.573585 | AK20: 46182 | AL20: Y | AM20: Y | AN20: =AS20-S20 -> 46311 | AS20: 46311
A21: Michael Ameling | B21: =VLOOKUP(A21,'Data Validation'!S:T,2,FALSE) -> Cross Architecture | C21: Yadav, Prashant<prashant.yadav03@sap.com> | D21: On-Mobile Device | E21: On-Mobile Device | F21: P2 | G21: S2 | H21: Y | I21: Incremental ONLY | J21: TripIt Mobile Android 10/2026 | K21: N/A | L21: 46310 | M21: 46314 | N21: GLOBAL | O21: Global | P21: Backlog | Q21: Y | AA21: 500000 | AB21: Open | AC21: No | AD21: =IF((AND((AS21-TODAY())<=30,(L21-TODAY())<=0,(F21="P1")))=TRUE,"Yes",IF(AND((AS21-TODAY())<=30,(L21-TODAY())<=0,(F21="P2"))=TRUE,"Yes","No")) -> No | AE21: =VLOOKUP(O21,'Data Validation'!I:J,2,FALSE) -> Global | AF21: =IF(AJ21<=53,AJ21,AJ21-52) -> 2.5849057 | AG21: =IF(H21="Y",(((160/1000000)*AA21)/5.3)*0.1,((160/1000000)*AA21)/5.3) -> 1.509434 | AH21: =SUM($AG$2:AG226) -> 679.24528 | AI21: =AH21/50 -> 13.584906 | AJ21: =WEEKNUM(TODAY())+AI21 -> 54.584906 | AK21: 46049 | AL21: Y | AM21: Y | AN21: =AS21-S21 -> 46314 | AS21: 46314
A22: Michael Ameling | B22: =VLOOKUP(A22,'Data Validation'!S:T,2,FALSE) -> Cross Architecture | C22: Yadav, Prashant<prashant.yadav03@sap.com> | D22: On-Mobile Device | E22: On-Mobile Device | F22: P2 | G22: S2 | H22: Y | I22: Incremental ONLY | J22: TripIt Mobile iOS 10/2026 | K22: N/A | L22: 46310 | M22: 46314 | N22: GLOBAL | O22: Global | P22: Backlog | Q22: Y | AA22: 500000 | AB22: Open | AC22: No | AD22: =IF((AND((AS22-TODAY())<=30,(L22-TODAY())<=0,(F22="P1")))=TRUE,"Yes",IF(AND((AS22-TODAY())<=30,(L22-TODAY())<=0,(F22="P2"))=TRUE,"Yes","No")) -> No | AE22: =VLOOKUP(O22,'Data Validation'!I:J,2,FALSE) -> Global | AF22: =IF(AJ22<=53,AJ22,AJ22-52) -> 2.6150943 | AG22: =IF(H22="Y",(((160/1000000)*AA22)/5.3)*0.1,((160/1000000)*AA22)/5.3) -> 1.509434 | AH22: =SUM($AG$2:AG227) -> 680.75472 | AI22: =AH22/50 -> 13.615094 | AJ22: =WEEKNUM(TODAY())+AI22 -> 54.615094 | AK22: 46049 | AL22: Y | AM22: Y | AN22: =AS22-S22 -> 46314 | AS22: 46314
A23: Stefan Steinle | B23: Customer Solution Support and Innovation | C23: Andreev, Ivan <ivan.andreev02@sap.com> | D23: On-Premise | E23: On-Premise | F23: P2 | G23: S2 | H23: Y | I23: Incremental ONLY | J23: SL Toolset for Cloud 2605Bb(T2026.27) | K23: N/A | L23: 46300 | M23: 46315 | N23: GTLC India | O23: Arpitha | P23: In Progress | Q23: Y | R23: 46301 | AA23: 500000 | AB23: Open | AC23: No | AD23: =IF((AND((AS23-TODAY())<=30,(L23-TODAY())<=0,(F24="P1")))=TRUE,"Yes",IF(AND((AS23-TODAY())<=30,(L23-TODAY())<=0,(F24="P2"))=TRUE,"Yes","No")) -> Yes | AE23: C5367590 | AF23: 22.415094 | AG23: 1.509434 | AH23: =SUM($AG$2:AG23) -> 33.207547 | AI23: 18.415094 | AJ23: 22.415094 | AK23: 46128 | AL23: Y | AM23: N | AN23: =AS23-S23 -> 46315 | AS23: 46315
A24: Peter Pluim | B24: Enterprise Cloud Services | C24: Yonchev, Tsonyo<tsonyo.yonchev@sap.com> | D24: On-Premise | E24: On-Premise | F24: P2 | G24: S2 | H24: Y | I24: Incremental ONLY | J24: LaMaRT 2026.20 | K24: 46117 | L24: 46304 | M24: 46321 | N24: GLOBAL | O24: Global | P24: Backlog | Q24: Y | AA24: 500000 | AB24: Open | AC24: No | AD24: =IF((AND((AS24-TODAY())<=30,(L25-TODAY())<=0,(F24="P1")))=TRUE,"Yes",IF(AND((AS24-TODAY())<=30,(L25-TODAY())<=0,(F24="P2"))=TRUE,"Yes","No")) -> Yes | AE24: =VLOOKUP(O24,'Data Validation'!I:J,2,FALSE) -> Global | AF24: =IF(AJ24<=53,AJ24,AJ24-52) -> 44.320755 | AG24: =IF(H24="Y",(((160/1000000)*AA24)/5.3)*0.1,((160/1000000)*AA24)/5.3) -> 1.509434 | AH24: =SUM($AG$2:AG66) -> 166.03774 | AI24: =AH24/50 -> 3.3207547 | AJ24: =WEEKNUM(TODAY())+AI24 -> 44.320755 | AK24: 46140 | AL24: Y | AM24: N | AN24: =AS24-S24 -> 46321 | AS24: 46321
A25: Peter Pluim | B25: =VLOOKUP(A25,'Data Validation'!S:T,2,FALSE) -> Enterprise Cloud Services | C25: Chakalova, Stela<stela.chakalova@sap.com> | D25: On-Premise | E25: On-Premise | F25: P2 | G25: S2 | H25: Y | I25: Incremental ONLY | J25: Edge Lifecycle Management 1.65 | K25: N/A | L25: 46297 | M25: 46325 | N25: GTLC India | O25: Arun | P25: In Progress | Q25: Y | R25: 46301 | AA25: 500000 | AB25: Open | AC25: No | AD25: =IF((AND((AS25-TODAY())<=30,(L25-TODAY())<=0,(F26="P1")))=TRUE,"Yes",IF(AND((AS25-TODAY())<=30,(L25-TODAY())<=0,(F26="P2"))=TRUE,"Yes","No")) -> Yes | AE25: =VLOOKUP(O25,'Data Validation'!I:J,2,FALSE) -> C5381614 | AF25: 22.173585 | AG25: 1.509434 | AH25: =SUM($AG$2:AG25) -> 36.226415 | AI25: 18.173585 | AJ25: 22.173585 | AK25: 46045 | AL25: Y | AM25: N | AN25: -15 | AS25: 46325
A26: Peter Pluim | B26: Enterprise Cloud Services | C26: Yonchev, Tsonyo<tsonyo.yonchev@sap.com> | D26: On-Premise | E26: On-Premise | F26: P2 | G26: S2 | H26: Y | I26: Incremental ONLY | J26: LaMaRT 2026.21 | K26: 46117 | L26: 46318 | M26: 46335 | N26: GLOBAL | O26: Global | P26: Backlog | Q26: Y | AA26: 500000 | AB26: Open | AC26: No | AD26: =IF((AND((AS26-TODAY())<=30,(L27-TODAY())<=0,(F26="P1")))=TRUE,"Yes",IF(AND((AS26-TODAY())<=30,(L27-TODAY())<=0,(F26="P2"))=TRUE,"Yes","No")) -> No | AE26: =VLOOKUP(O26,'Data Validation'!I:J,2,FALSE) -> Global | AF26: =IF(AJ26<=53,AJ26,AJ26-52) -> 44.350943 | AG26: =IF(H26="Y",(((160/1000000)*AA26)/5.3)*0.1,((160/1000000)*AA26)/5.3) -> 1.509434 | AH26: =SUM($AG$2:AG67) -> 167.54717 | AI26: =AH26/50 -> 3.3509434 | AJ26: =WEEKNUM(TODAY())+AI26 -> 44.350943 | AK26: 46140 | AL26: Y | AM26: N | AN26: =AS26-S26 -> 46335 | AS26: 46335
A27: Michael Ameling | B27: =VLOOKUP(A27,'Data Validation'!S:T,2,FALSE) -> Cross Architecture | C27: Singh, Shubham<shubham.singh04@sap.com> | D27: On-Premise | E27: On-Premise | F27: P2 | G27: S2 | H27: Y | I27: Incremental ONLY | J27: APIM_EDGE_IC_2610 | K27: N/A | L27: 46311 | M27: 46339 | N27: GLOBAL | O27: Global | P27: Backlog | Q27: Y | AA27: 500000 | AB27: Open | AC27: No | AD27: =IF((AND((AS27-TODAY())<=30,(L27-TODAY())<=0,(F29="P1")))=TRUE,"Yes",IF(AND((AS27-TODAY())<=30,(L27-TODAY())<=0,(F29="P2"))=TRUE,"Yes","No")) -> No | AE27: =VLOOKUP(O27,'Data Validation'!I:J,2,FALSE) -> Global | AF27: =IF(AJ27<=53,AJ27,AJ27-52) -> 41.784906 | AG27: =IF(H27="Y",(((160/1000000)*AA27)/5.3)*0.1,((160/1000000)*AA27)/5.3) -> 1.509434 | AH27: =SUM($AG$2:AG27) -> 39.245283 | AI27: =AH27/50 -> 0.78490566 | AJ27: =WEEKNUM(TODAY())+AI27 -> 41.784906 | AK27: 46122 | AL27: Y | AM27: N | AN27: =AS27-S27 -> 46339 | AS27: 46339
A28: Michael Ameling | B28: =VLOOKUP(A28,'Data Validation'!S:T,2,FALSE) -> Cross Architecture | C28: Yadav, Prashant<prashant.yadav03@sap.com> | D28: On-Mobile Device | E28: On-Mobile Device | F28: P2 | G28: S2 | H28: Y | I28: Incremental ONLY | J28: SAP Concur Mobile iOS H1 2026 - Nov | K28: N/A | L28: 46337 | M28: 46342 | N28: GLOBAL | O28: Global | P28: Backlog | Q28: Y | AA28: 500000 | AB28: Open | AC28: No | AD28: =IF((AND((AS28-TODAY())<=30,(L28-TODAY())<=0,(F76="P1")))=TRUE,"Yes",IF(AND((AS28-TODAY())<=30,(L28-TODAY())<=0,(F76="P2"))=TRUE,"Yes","No")) -> No | AE28: =VLOOKUP(O28,'Data Validation'!I:J,2,FALSE) -> Global | AF28: =IF(AJ28<=53,AJ28,AJ28-52) -> 41.815094 | AG28: =IF(H28="Y",(((160/1000000)*AA28)/5.3)*0.1,((160/1000000)*AA28)/5.3) -> 1.509434 | AH28: =SUM($AG$2:AG28) -> 40.754717 | AI28: =AH28/50 -> 0.81509434 | AJ28: =WEEKNUM(TODAY())+AI28 -> 41.815094 | AK28: 46182 | AL28: Y | AM28: Y | AN28: =AS28-S28 -> 46342 | AS28: 46342
A29: Michael Ameling | B29: =VLOOKUP(A29,'Data Validation'!S:T,2,FALSE) -> Cross Architecture | C29: Yadav, Prashant<prashant.yadav03@sap.com> | D29: On-Mobile Device | E29: On-Mobile Device | F29: P2 | G29: S2 | H29: Y | I29: Incremental ONLY | J29: SAP Concur Mobile Android H1 2026 - Nov | K29: N/A | L29: 46337 | M29: 46342 | N29: GLOBAL | O29: Global | P29: Backlog | Q29: Y | AA29: 500000 | AB29: Open | AC29: No | AD29: =IF((AND((AS29-TODAY())<=30,(L29-TODAY())<=0,(F77="P1")))=TRUE,"Yes",IF(AND((AS29-TODAY())<=30,(L29-TODAY())<=0,(F77="P2"))=TRUE,"Yes","No")) -> No | AE29: =VLOOKUP(O29,'Data Validation'!I:J,2,FALSE) -> Global | AF29: =IF(AJ29<=53,AJ29,AJ29-52) -> 41.845283 | AG29: =IF(H29="Y",(((160/1000000)*AA29)/5.3)*0.1,((160/1000000)*AA29)/5.3) -> 1.509434 | AH29: =SUM($AG$2:AG29) -> 42.264151 | AI29: =AH29/50 -> 0.84528302 | AJ29: =WEEKNUM(TODAY())+AI29 -> 41.845283 | AK29: 46182 | AL29: Y | AM29: Y | AN29: =AS29-S29 -> 46342 | AS29: 46342
A30: Stefan Steinle | B30: Customer Solution Support and Innovation | C30: Andreev, Ivan <ivan.andreev02@sap.com> | D30: On-Premise | E30: On-Premise | F30: P2 | G30: S2 | H30: Y | I30: Incremental ONLY | J30: SL Toolset for Cloud 2605Bb(T2026.27) | K30: N/A | L30: 46328 | M30: 46343 | N30: GLOBAL | O30: Global | P30: Backlog | Q30: Y | AA30: 500000 | AB30: Open | AC30: No | AD30: =IF((AND((AS30-TODAY())<=30,(L30-TODAY())<=0,(F32="P1")))=TRUE,"Yes",IF(AND((AS30-TODAY())<=30,(L30-TODAY())<=0,(F32="P2"))=TRUE,"Yes","No")) -> No | AE30: C5367590 | AF30: 22.415094 | AG30: 1.509434 | AH30: =SUM($AG$2:AG30) -> 43.773585 | AI30: 18.415094 | AJ30: 22.415094 | AK30: 46128 | AL30: Y | AM30: N | AN30: =AS30-S30 -> 46343 | AS30: 46343
A31: Peter Pluim | B31: Enterprise Cloud Services | C31: Yonchev, Tsonyo<tsonyo.yonchev@sap.com> | D31: On-Premise | E31: On-Premise | F31: P2 | G31: S2 | H31: Y | I31: Incremental ONLY | J31: LaMaRT 2026.22 | K31: 46117 | L31: 46332 | M31: 46349 | N31: GLOBAL | O31: Global | P31: Backlog | Q31: Y | AA31: 500000 | AB31: Open | AC31: No | AD31: =IF((AND((AS31-TODAY())<=30,(L32-TODAY())<=0,(F31="P1")))=TRUE,"Yes",IF(AND((AS31-TODAY())<=30,(L32-TODAY())<=0,(F31="P2"))=TRUE,"Yes","No")) -> No | AE31: =VLOOKUP(O31,'Data Validation'!I:J,2,FALSE) -> Global | AF31: =IF(AJ31<=53,AJ31,AJ31-52) -> 44.501887 | AG31: =IF(H31="Y",(((160/1000000)*AA31)/5.3)*0.1,((160/1000000)*AA31)/5.3) -> 1.509434 | AH31: =SUM($AG$2:AG72) -> 175.09434 | AI31: =AH31/50 -> 3.5018868 | AJ31: =WEEKNUM(TODAY())+AI31 -> 44.501887 | AK31: 46140 | AL31: Y | AM31: N | AN31: =AS31-S31 -> 46349 | AS31: 46349
A32: Peter Pluim | B32: =VLOOKUP(A32,'Data Validation'!S:T,2,FALSE) -> Enterprise Cloud Services | C32: Chakalova, Stela<stela.chakalova@sap.com> | D32: On-Premise | E32: On-Premise | F32: P2 | G32: S2 | H32: Y | I32: Incremental ONLY | J32: Edge Lifecycle Management 1.66 | K32: N/A | L32: 46325 | M32: 46353 | N32: GLOBAL | O32: Global | P32: Backlog | Q32: Y | AA32: 500000 | AB32: Open | AC32: No | AD32: =IF((AND((AS32-TODAY())<=30,(L32-TODAY())<=0,(#REF!="P1")))=TRUE,"Yes",IF(AND((AS32-TODAY())<=30,(L32-TODAY())<=0,(#REF!="P2"))=TRUE,"Yes","No")) -> #REF! | AE32: =VLOOKUP(O32,'Data Validation'!I:J,2,FALSE) -> Global | AF32: 22.173585 | AG32: 1.509434 | AH32: =SUM($AG$2:AG32) -> 46.792453 | AI32: 18.173585 | AJ32: 22.173585 | AK32: 46045 | AL32: Y | AM32: N | AN32: -15 | AS32: 46353
A33: Peter Pluim | B33: Enterprise Cloud Services | C33: Yonchev, Tsonyo<tsonyo.yonchev@sap.com> | D33: On-Premise | E33: On-Premise | F33: P2 | G33: S2 | H33: Y | I33: Incremental ONLY | J33: LaMaRT 2026.23 | K33: 46117 | L33: 46346 | M33: 46363 | N33: GLOBAL | O33: Global | P33: Backlog | Q33: Y | AA33: 500000 | AB33: Open | AC33: No | AD33: =IF((AND((AS33-TODAY())<=30,(L34-TODAY())<=0,(F33="P1")))=TRUE,"Yes",IF(AND((AS33-TODAY())<=30,(L34-TODAY())<=0,(F33="P2"))=TRUE,"Yes","No")) -> No | AE33: =VLOOKUP(O33,'Data Validation'!I:J,2,FALSE) -> Global | AF33: =IF(AJ33<=53,AJ33,AJ33-52) -> 44.562264 | AG33: =IF(H33="Y",(((160/1000000)*AA33)/5.3)*0.1,((160/1000000)*AA33)/5.3) -> 1.509434 | AH33: =SUM($AG$2:AG74) -> 178.11321 | AI33: =AH33/50 -> 3.5622642 | AJ33: =WEEKNUM(TODAY())+AI33 -> 44.562264 | AK33: 46140 | AL33: Y | AM33: N | AN33: =AS33-S33 -> 46363 | AS33: 46363
A34: Michael Ameling | B34: =VLOOKUP(A34,'Data Validation'!S:T,2,FALSE) -> Cross Architecture | C34: Yadav, Prashant<prashant.yadav03@sap.com> | D34: On-Mobile Device | E34: On-Mobile Device | F34: P2 | G34: S2 | H34: Y | I34: Incremental ONLY | J34: TripIt Mobile Android 11/2026 | K34: N/A | L34: 46359 | M34: 46363 | N34: GLOBAL | O34: Global | P34: Backlog | Q34: Y | AA34: 500000 | AB34: Open | AC34: No | AD34: =IF((AND((AS34-TODAY())<=30,(L34-TODAY())<=0,(F34="P1")))=TRUE,"Yes",IF(AND((AS34-TODAY())<=30,(L34-TODAY())<=0,(F34="P2"))=TRUE,"Yes","No")) -> No | AE34: =VLOOKUP(O34,'Data Validation'!I:J,2,FALSE) -> Global | AF34: =IF(AJ34<=53,AJ34,AJ34-52) -> 2.9773585 | AG34: =IF(H34="Y",(((160/1000000)*AA34)/5.3)*0.1,((160/1000000)*AA34)/5.3) -> 1.509434 | AH34: =SUM($AG$2:AG239) -> 698.86792 | AI34: =AH34/50 -> 13.977358 | AJ34: =WEEKNUM(TODAY())+AI34 -> 54.977358 | AK34: 46049 | AL34: Y | AM34: Y | AN34: =AS34-S34 -> 46363 | AS34: 46363
A35: Michael Ameling | B35: =VLOOKUP(A35,'Data Validation'!S:T,2,FALSE) -> Cross Architecture | C35: Yadav, Prashant<prashant.yadav03@sap.com> | D35: On-Mobile Device | E35: On-Mobile Device | F35: P2 | G35: S2 | H35: Y | I35: Incremental ONLY | J35: TripIt Mobile iOS 11/2026 | K35: N/A | L35: 46359 | M35: 46363 | N35: GLOBAL | O35: Global | P35: Backlog | Q35: Y | AA35: 500000 | AB35: Open | AC35: No | AD35: =IF((AND((AS35-TODAY())<=30,(L35-TODAY())<=0,(F35="P1")))=TRUE,"Yes",IF(AND((AS35-TODAY())<=30,(L35-TODAY())<=0,(F35="P2"))=TRUE,"Yes","No")) -> No | AE35: =VLOOKUP(O35,'Data Validation'!I:J,2,FALSE) -> Global | AF35: =IF(AJ35<=53,AJ35,AJ35-52) -> 3.0075472 | AG35: =IF(H35="Y",(((160/1000000)*AA35)/5.3)*0.1,((160/1000000)*AA35)/5.3) -> 1.509434 | AH35: =SUM($AG$2:AG240) -> 700.37736 | AI35: =AH35/50 -> 14.007547 | AJ35: =WEEKNUM(TODAY())+AI35 -> 55.007547 | AK35: 46049 | AL35: Y | AM35: Y | AN35: =AS35-S35 -> 46363 | AS35: 46363
A36: Michael Ameling | B36: =VLOOKUP(A36,'Data Validation'!S:T,2,FALSE) -> Cross Architecture | C36: Yadav, Prashant<prashant.yadav03@sap.com> | D36: On-Mobile Device | E36: On-Mobile Device | F36: P2 | G36: S2 | H36: Y | I36: Incremental ONLY | J36: SAP Concur Mobile iOS H1 2026 - Dec | K36: N/A | L36: 46363 | M36: 46370 | N36: GLOBAL | O36: Global | P36: Backlog | Q36: Y | AA36: 500000 | AB36: Open | AC36: No | AD36: =IF((AND((AS36-TODAY())<=30,(L36-TODAY())<=0,(F84="P1")))=TRUE,"Yes",IF(AND((AS36-TODAY())<=30,(L36-TODAY())<=0,(F84="P2"))=TRUE,"Yes","No")) -> No | AE36: =VLOOKUP(O36,'Data Validation'!I:J,2,FALSE) -> Global | AF36: =IF(AJ36<=53,AJ36,AJ36-52) -> 42.056604 | AG36: =IF(H36="Y",(((160/1000000)*AA36)/5.3)*0.1,((160/1000000)*AA36)/5.3) -> 1.509434 | AH36: =SUM($AG$2:AG36) -> 52.830189 | AI36: =AH36/50 -> 1.0566038 | AJ36: =WEEKNUM(TODAY())+AI36 -> 42.056604 | AK36: 46182 | AL36: Y | AM36: Y | AN36: =AS36-S36 -> 46370 | AS36: 46370
A37: Michael Ameling | B37: =VLOOKUP(A37,'Data Validation'!S:T,2,FALSE) -> Cross Architecture | C37: Yadav, Prashant<prashant.yadav03@sap.com> | D37: On-Mobile Device | E37: On-Mobile Device | F37: P2 | G37: S2 | H37: Y | I37: Incremental ONLY | J37: SAP Concur Mobile Android H1 2026 - Dec | K37: N/A | L37: 46363 | M37: 46370 | N37: GLOBAL | O37: Global | P37: Backlog | Q37: Y | AA37: 500000 | AB37: Open | AC37: No | AD37: =IF((AND((AS37-TODAY())<=30,(L37-TODAY())<=0,(F85="P1")))=TRUE,"Yes",IF(AND((AS37-TODAY())<=30,(L37-TODAY())<=0,(F85="P2"))=TRUE,"Yes","No")) -> No | AE37: =VLOOKUP(O37,'Data Validation'!I:J,2,FALSE) -> Global | AF37: =IF(AJ37<=53,AJ37,AJ37-52) -> 42.086792 | AG37: =IF(H37="Y",(((160/1000000)*AA37)/5.3)*0.1,((160/1000000)*AA37)/5.3) -> 1.509434 | AH37: =SUM($AG$2:AG37) -> 54.339623 | AI37: =AH37/50 -> 1.0867925 | AJ37: =WEEKNUM(TODAY())+AI37 -> 42.086792 | AK37: 46182 | AL37: Y | AM37: Y | AN37: =AS37-S37 -> 46370 | AS37: 46370
A38: Michael Ameling | B38: =VLOOKUP(A38,'Data Validation'!S:T,2,FALSE) -> Cross Architecture | C38: Singh, Shubham<shubham.singh04@sap.com> | D38: On-Premise | E38: On-Premise | F38: P2 | G38: S2 | H38: Y | I38: Incremental ONLY | J38: APIM_EDGE_IC_2611 | K38: N/A | L38: 46339 | M38: 46371 | N38: GLOBAL | O38: Global | P38: Backlog | Q38: Y | AA38: 500000 | AB38: Open | AC38: No | AD38: =IF((AND((AS38-TODAY())<=30,(L38-TODAY())<=0,(F40="P1")))=TRUE,"Yes",IF(AND((AS38-TODAY())<=30,(L38-TODAY())<=0,(F40="P2"))=TRUE,"Yes","No")) -> No | AE38: =VLOOKUP(O38,'Data Validation'!I:J,2,FALSE) -> Global | AF38: =IF(AJ38<=53,AJ38,AJ38-52) -> 42.116981 | AG38: =IF(H38="Y",(((160/1000000)*AA38)/5.3)*0.1,((160/1000000)*AA38)/5.3) -> 1.509434 | AH38: =SUM($AG$2:AG38) -> 55.849057 | AI38: =AH38/50 -> 1.1169811 | AJ38: =WEEKNUM(TODAY())+AI38 -> 42.116981 | AK38: 46122 | AL38: Y | AM38: N | AN38: =AS38-S38 -> 46371 | AS38: 46371
A39: Peter Pluim | B39: Enterprise Cloud Services | C39: Yonchev, Tsonyo<tsonyo.yonchev@sap.com> | D39: On-Premise | E39: On-Premise | F39: P2 | G39: S2 | H39: Y | I39: Incremental ONLY | J39: LaMaRT 2026.24 | K39: 46117 | L39: 46360 | M39: 46377 | N39: GLOBAL | O39: Global | P39: Backlog | Q39: Y | AA39: 500000 | AB39: Open | AC39: No | AD39: No | AE39: =VLOOKUP(O39,'Data Validation'!I:J,2,FALSE) -> Global | AF39: =IF(AJ39<=53,AJ39,AJ39-52) -> 45.316981 | AG39: =IF(H39="Y",(((160/1000000)*AA39)/5.3)*0.1,((160/1000000)*AA39)/5.3) -> 1.509434 | AH39: =SUM($AG$2:AG81) -> 215.84906 | AI39: =AH39/50 -> 4.3169811 | AJ39: =WEEKNUM(TODAY())+AI39 -> 45.316981 | AK39: 46140 | AL39: Y | AM39: N | AN39: =AS39-S39 -> 46377 | AS39: 46377
A40: Peter Pluim | B40: =VLOOKUP(A40,'Data Validation'!S:T,2,FALSE) -> Enterprise Cloud Services | C40: Chakalova, Stela<stela.chakalova@sap.com> | D40: On-Premise | E40: On-Premise | F40: P2 | G40: S2 | H40: Y | I40: Incremental ONLY | J40: Edge Lifecycle Management 1.67 | K40: N/A | L40: 46353 | M40: 46381 | N40: GLOBAL | O40: Global | P40: Backlog | Q40: Y | AA40: 500000 | AB40: Open | AC40: No | AD40: =IF((AND((AS40-TODAY())<=30,(L40-TODAY())<=0,(F36="P1")))=TRUE,"Yes",IF(AND((AS40-TODAY())<=30,(L40-TODAY())<=0,(F36="P2"))=TRUE,"Yes","No")) -> No | AE40: =VLOOKUP(O40,'Data Validation'!I:J,2,FALSE) -> Global | AF40: 22.173585 | AG40: 1.509434 | AH40: =SUM($AG$2:AG40) -> 58.867925 | AI40: 18.173585 | AJ40: 22.173585 | AK40: 46045 | AL40: Y | AM40: N | AN40: -15 | AS40: 46381
...

Sheet Wiki
A1: SAP User Enabl Mgmt SE | B1: Source Code | C1: On-Premise | D1: P1 | E1: N | F1: 305012457_CAE_Boehringer_Ingelheim | G1: 45998 | H1: C5385241
A2: SAP User Enabl Mgmt SE | B2: On-Premise | C2: On-Premise | D2: P1 | E2: N | F2: QRO Online Enhancements Release3e | G2: 46045 | H2: C5366020
A3: SAP User Enabl Mgmt SE | B3: On-Premise | C3: On-Premise | D3: P1 | E3: N | F3: QRO Online Enhancements Release3e-CF source code | G3: 46087 | H3: C5366020
A4: SAP User Enabl Mgmt SE | B4: On-Premise | C4: On-Premise | D4: P1 | E4: N | F4: 306181513_Sprint 0 T-Systems | G4: 46155 | H4: C5366020
A5: People Growth Management Office UK | B5: On-Mobile Device | C5: On-Mobile Device | D5: P1 | E5: N | F5: Rural Sourcing Management 2607 | G5: 46233 | H5: I540507
A6: Cross Architecture | B6: Outbound OEM | C6: On-Premise | D6: P1 | E6: Y | F6: SDK 16.1 SP00 PL02 | G6: 46087 | H6: I758150
A7: Cross Architecture | B7: Outbound OEM | C7: On-Premise | D7: P1 | E7: Y | F7: OS 16.1 SP00 PL02 | G7: 46087 | H7: I762314
A8: Cross Architecture | B8: Outbound OEM | C8: On-Premise | D8: P1 | E8: Y | F8: ASE 16.1 SP00 PL02 | G8: 46087 | H8: I758015
A9: Cross Architecture | B9: Outbound OEM | C9: On-Premise | D9: P1 | E9: Y | F9: SRS 16.1 SP00 PL02 | G9: 46087 | H9: I758929
A10: Strategy & Transformation, Customer Success | B10: Outbound OEM | C10: On-Premise | D10: P1 | E10: Y | F10: SAP Convergent Charging 2025_FPS1 | G10: 46091 | H10: I559269
A11: Cross Architecture | B11: Source Code | C11: On-Premise | D11: P1 | E11: Y | F11: Telco and Utilities Accelerator 2026-02-JDK21 | G11: 46092 | H11: C5403671
A12: SAP HANA Database & Analytics | B12: Outbound OEM | C12: On-Premise | D12: P1 | E12: Y | F12: SAP HANA Cloud Integration,DS 2603 (1.0.11.60) | G12: 46101 | H12: I559269
... A146: SAP User Enabl Mgmt SE | B146: On-Premise | C146: On-Premise | D146: P2 | E146: Y | F146: 305974898_CAE RUN_NEO to CF Migration_Iren | G146: 46157 | H146: C5385241
B147: On-Premise | C147: On-Premise | D147: P2 | E147: Y | F147: FinProdSubledger 3.5 | G147: 46164 | H147: C5385241
A148: ISBN CloudOps Cross COPS | B148: On-Mobile Device | C148: On-Mobile Device | D148: P2 | E148: Y | F148: B1 Service App for iOS 1.0 PL20 | G148: 46164 | H148: C5385241
A149: ISBN CloudOps Cross COPS | B149: On-Mobile Device | C149: On-Mobile Device | D149: P2 | E149: Y | F149: B1 Service App for Android 1.0 PL14 | G149: 46164 | H149: C5385241
A150: Cross Architecture | B150: On-Premise | C150: On-Premise | D150: P2 | E150: Y | F150: FRUN 5.0 FP03 | G150: 46167 | H150: C5367590
A151: Enterprise Cloud Services | B151: On-Premise | C151: On-Premise | D151: P2 | E151: Y | F151: LaMaRT 2026.09 | G151: 46167 | H151: I757367
A152: ISBN CloudOps Cross COPS | B152: On-Mobile Device | C152: On-Mobile Device | D152: P2 | E152: Y | F152: B1 Mobile App for iOS 1.11 PL24 | G152: 46168 | H152: C5385241
A153: ISBN CloudOps Cross COPS | B153: On-Mobile Device | C153: On-Mobile Device | D153: P2 | E153: Y | F153: B1 Mobile App for Android 1.2 PL18 | G153: 46168 | H153: C5385241
A154: SAP S/4 HANA | B154: On-Mobile Device | C154: On-Mobile Device | D154: P2 | E154: Y | F154: SAP Sports One 1.0 - on Mobile - 2605 | G154: 46169 | H154: Global
A155: Cross Architecture | B155: On-Premise | C155: On-Premise | D155: P2 | E155: Y | F155: SAP Business Client 8.10 (Beta2) | G155: 46169 | H155: C5385241
A156: SAP S/4 HANA | B156: On-Mobile Device | C156: On-Mobile Device | D156: P2 | E156: Y | F156: SAP Sports One 1.0 - on Mobile - 2605 | G156: 46169 | H156: Global
A157: Cross Architecture | B157: On-Mobile Device | C157: On-Mobile Device | D157: P2 | E157: Y | F157: Complete Android H1 1.1(June 2026) | G157: 46170 | H157: C5381614
A158: Cross Architecture | B158: On-Mobile Device | C158: On-Mobile Device | D158: P2 | E158: Y | F158: Complete iOS H1 1.1(June 2026) | G158: 46170 | H158: C5381614
A159: Cross Architecture | B159: On-Mobile Device | C159: On-Mobile Device | D159: P2 | E159: Y | F159: SAP Concur Mobile iOS H1 2026 - May | G159: 46170 | H159: C5403671
... A307: ISBN CloudOps Cross COPS | B307: On-Demand (SaaS) | C307: On-Demand (SaaS) | D307: P3 | E307: Y | F307: ABAP in SAP BTP 2605 | G307: 46141 | H307: I501689

Sheet 2023_P3 IP Scan Removal
A1: L1 Manager | B1: L1 Development Unit | C1: Dev Contact | D1: Program Category | E1: Delivery Mode | F1: Priority | G1: Severity | H1: Previously Scanned | I1: Scan Category | J1: Program | K1: Start of Development | L1: End of Development | M1: RTC | N1: Location | O1: FOSS Analyst | P1: FOSS Scan State | Q1: Black Duck Scan | R1: FOSS Scan Assigned | S1: FOSS Scan Closed | T1: Commercial Scan Status | U1: Comm Analyst | V1: CTP Scan Ticket JIRA link | W1: Web Service Scan Status | X1: Web Service Analyst | Y1: WS Scan Ticket JIRA link | Z1: Comments | AA1: SLOC Count | AB1: Tracking System Ticket Status | AC1: RTC Passed | AD1: Recommended to Request Exemption | AE1: Owner # | AF1: Estimated Calendar Week (CW) for the scan to be "In Progress" | AG1: Estimated # of days to complete the first round of scan | AH1: Cumulative Days | AI1: CW to be added to the current CW | AJ1: Estimated CW for scan to be in progress | AK1: Scan Submission Date | AL1: Continuous scan
A2: Irfan Khan | B2: SAP HANA Database & Analytics | C2: JANOT, Nicolas <nicolas.janot@sap.com>; SIRE, Philippe <philippe.sire@sap.com> | D2: Docker Container | E2: On-Demand (SaaS) | F2: P3 | G2: S1 | H2: N | I2: OneTime Scan | J2: [Docker] SAC OD 2021.12 | K2: 44198 | L2: 44320 | M2: 44347 | N2: GLOBAL | O2: GLOBAL | P2: Backlog | AA2: 500000 | AB2: Open | AC2: No | AD2: No | AE2: Global | AF2: 2.720771 | AG2: 15.09434 | AH2: 86.038548 | AI2: 1.720771 | AJ2: 2.720771
A3: Michael Paul Weingartner | B3: SAP BTP Core | C3: Krastev, Anatoli <anatoli.krastev@sap.com>; Georgiev, Georgi <g.georgiev@sap.com> | D3: Docker Container | E3: On-Demand (SaaS) | F3: P3 | G3: S2 | H3: Y | I3: OneTime Scan | J3: [Docker] FS on K8s Delivery 2106a | K3: 44354 | L3: 44365 | M3: 44379 | N3: GLOBAL | O3: GLOBAL | P3: Backlog | V3: https://jira.tools.sap/browse/CTPSAPPRODUCT-4604 | Y3: https://jira.tools.sap/browse/WEBSERVSAPPRODUCT-3556 | Z3: Awaiting dev information for future releases. | AA3: 500000 | AB3: Open | AC3: No | AD3: No | AE3: Global | AF3: 2.7811483 | AG3: 1.509434 | AH3: 89.057416 | AI3: 1.7811483 | AJ3: 2.7811483 | AK3: 44627 | AL3: Y
A4: Michael Paul Weingartner | B4: SAP BTP Core | C4: Jain, Swati <swati.jain01@sap.com>; DL_5D44036925A7520279676E48@global.corp.sap <DL_5D44036925A7520279676E48@global.corp.sap> | D4: Docker Container | E4: On-Demand (SaaS) | F4: P3 | G4: S2 | H4: Y | I4: OneTime Scan | J4: [Docker] FS on K8s Delivery 2106b | L4: 44379 | M4: 44392 | N4: GLOBAL | O4: GLOBAL | P4: Backlog | V4: https://jira.tools.sap/browse/CTPSAPPRODUCT-4621 | W4: In Progress | X4: Yi Zhang | Y4: https://jira.tools.sap/browse/WEBSERVSAPPRODUCT-3572 | Z4: Export scan assigned to Chaitanya | AA4: 500000 | AB4: Open | AC4: No | AD4: No | AE4: Global | AF4: 2.7811483 | AG4: 1.509434 | AH4: 89.057416 | AI4: 1.7811483 | AJ4: 2.7811483 | AK4: 44720
A5: Michael Paul Weingartner | B5: SAP BTP Core | C5: Jain, Swati <swati.jain01@sap.com>; DL_5D44036925A7520279676E48@global.corp.sap | D5: Docker Container | E5: On-Demand (SaaS) | F5: P3 | G5: S2 | H5: Y | I5: OneTime Scan | J5: [Docker] FS on K8s Delivery 2108b | L5: 44437 | M5: 44449 | N5: GLOBAL | O5: GLOBAL | P5: Backlog | V5: https://jira.tools.sap/browse/CTPSAPPRODUCT-4605 | W5: In Progress | X5: Komal | Y5: https://jira.tools.sap/browse/WEBSERVSAPPRODUCT-3557 | Z5: Export scan assigned to Chaitanya | AA5: 500002 | AB5: Open | AC5: No | AD5: No | AE5: Global | AF5: 2.8113371 | AG5: 1.50944 | AH5: 90.566856 | AI5: 1.8113371 | AJ5: 2.8113371 | AK5: 44641
A6: Michael Paul Weingartner | B6: SAP BTP Core | C6: Jain, Swati <swati.jain01@sap.com>; DL_5D44036925A7520279676E48@global.corp.sap | D6: Docker Container | E6: On-Demand (SaaS) | F6: P3 | G6: S2 | H6: Y | I6: OneTime Scan | J6: [Docker] FS on K8s Delivery 2109b | L6: 44463 | M6: 44476 | N6: GLOBAL | O6: GLOBAL | P6: Backlog | V6: https://jira.tools.sap/browse/CTPSAPPRODUCT-4628 | W6: In Progress | X6: Yi Zhang | Y6: https://jira.tools.sap/browse/WEBSERVSAPPRODUCT-3580 | Z6: Export scan assigned to Sandhya | AA6: 500002 | AB6: Open | AC6: No | AD6: No | AE6: Global | AF6: 2.8415259 | AG6: 1.50944 | AH6: 92.076296 | AI6: 1.8415259 | AJ6: 2.8415259 | AK6: 44735

Sheet 2022_P3 IP Scan Removal
A1: L1 Manager | B1: L1 Development Unit | C1: Dev Contact | D1: Program Category | E1: Delivery Mode | F1: Priority | G1: Severity | H1: Previously Scanned | I1: Scan Category | J1: Program | K1: Start of Development | L1: End of Development | M1: RDM | N1: RTC | O1: Location | P1: FOSS Analyst | Q1: FOSS Scan State | R1: Black Duck Scan | S1: FOSS Scan Assigned | T1: FOSS Scan Closed | U1: Commercial Scan Status | V1: Comm Analyst | W1: CTP Scan Ticket JIRA link | X1: Web Service Scan Status | Y1: Web Service Analyst | Z1: WS Scan Ticket JIRA link | AA1: Comments | AB1: SLOC Count | AC1: Tracking System Ticket Status | AD1: RTC Passed | AE1: Recommended to Request Exemption | AF1: Owner # | AG1: Estimated Calendar Week (CW) for the scan to be "In Progress" | AH1: Estimated # of days to complete the first round of scan | AI1: Cumulative Days | AJ1: CW to be added to the current CW | AK1: Estimated CW for scan to be in progress | AL1: Scan Submission Date | AM1: Continuous scan
A2: Michael Paul Weingartner | B2: SAP BTP Core | C2: Mager-Bruhn, Nicole <nicole.mager-bruhn@sap.com> | D2: On-Demand (SaaS) | E2: On-Demand (SaaS) | F2: P3 | G2: S1 | H2: N | I2: Incremental ONLY | J2: SAP Master Data Governance, cloud edition 2202 | K2: 44473 | L2: 44519 | N2: 44611 | O2: GLOBAL | P2: GLOBAL | Q2: Backlog | W2: https://jira.tools.sap/browse/CTPSAPPRODUCT-4600 | X2: 500000 | Y2: Open | Z2: https://jira.tools.sap/browse/WEBSERVSAPPRODUCT-3552 | AA2: Export Scan required - Siva | AB2: 500000 | AC2: Open | AD2: No | AE2: No | AF2: GLOBAL | AG2: 7.7698147 | AH2: 15.09434 | AI2: 238.49074 | AJ2: 4.7698147 | AK2: 7.7698147 | AL2: 44615
A3: Harald Kuck | B3: TI ABAP Platform Mgmt (SE) | C3: Hong, Gyeongsu <gyeongsu.hong@sap.com> | D3: On-Demand (SaaS) | E3: On-Demand (SaaS) | F3: P3 | G3: S2 | H3: Y | I3: Incremental ONLY | J3: ABAP in SAP BTP 2211 | K3: 44735 | L3: 44781 | M3: 44854 | N3: 44862 | O3: GTLC Germany | P3: Ravi | Q3: Done | S3: 44816 | T3: 44818 | AB3: 500001 | AC3: Open | AD3: No | AE3: No | AF3: D072009 | AG3: 27.241529 | AH3: 1.509437 | AI3: 1212.0764 | AJ3: 24.241529 | AK3: 27.241529 | AL3: 44813

Sheet 2024 Done
A1: L1 Manager | B1: L1 Development Unit | C1: Dev Contact | D1: Program Category | E1: Delivery Mode | F1: Priority | G1: Severity | H1: Previously Scanned | I1: Scan Category | J1: Program | K1: Start of Development | L1: End of Development | M1: RDM | N1: RTC | O1: Location | P1: FOSS Analyst | Q1: FOSS Scan State | R1: Black Duck Scan | S1: FOSS Scan Assigned | T1: FOSS Scan Closed | U1: Commercial Scan Status | V1: Comm Analyst | W1: CTP Scan Ticket JIRA link | X1: Web Service Scan Status | Y1: Web Service Analyst | Z1: WS Scan Ticket JIRA link | AA1: Comments | AB1: SLOC Count | AC1: Tracking System Ticket Status | AD1: RTC Passed | AE1: Recommended to Request Exemption | AF1: Owner # | AG1: Estimated Calendar Week (CW) for the scan to be "In Progress" | AH1: Estimated # of days to complete the first round of scan | AI1: Cumulative Days | AJ1: CW to be added to the current CW | AK1: Estimated CW for scan to be in progress | AL1: Scan Submission Date | AM1: Continuous scan | AN1: Crown Jewel | AO1: Closed within SLA
A2: Claudio Muruzabal | B2: EMEA South, Customer Success | C2: Sikri, Sanjam <sanjam.sikri@sap.com> | D2: Source Code | E2: On-Premise | F2: P1 | G2: S1 | H2: N | I2: Incremental ONLY | J2: 304749634_CSD_TOYOTA_TSUSHO | L2: 45233 | M2: 45609 | N2: 45280 | O2: GTLC Germany | P2: Ravi | Q2: Done | R2: Y | S2: 45272 | T2: 45279 | AB2: 500002 | AC2: Open | AD2: No | AE2: Yes | AF2: D072009 | AG2: 6.9622654 | AH2: 15.0944 | AI2: 98.113268 | AJ2: 1.9622654 | AK2: 6.9622654 | AL2: 45272 | AN2: N | AO2: 1
A3: Irfan Khan | B3: SAP HANA Database & Analytics | C3: Chennappa Krishnamurthy, Lavanya <lavanya.chennappa.krishnamurthy@sap.com> | D3: Source Code | E3: On-Premise | F3: P1 | G3: S1 | H3: Y | I3: Incremental ONLY | J3: SAP Data Intelligence 3.3 | L3: 45264 | M3: 45615 | N3: 45284 | O3: GTLC Germany | P3: Giang | Q3: Done | R3: Y | S3: 45364 | T3: 45479 | U3: In Progress | V3: Chaitanya | W3: https://jira.tools.sap/browse/CTPSAPPRODUCT-4714 | X3: In Progress | Y3: Chaitanya | Z3: https://jira.tools.sap/browse/WEBSERVSAPPRODUCT-3666 | AA3: Export Scan required - Chaitanya | Reassigned from Chaitanya | AB3: 500000 | AC3: Open | AD3: No | AE3: Yes | AF3: I540507 | AG3: 6.992454 | AH3: 1.509434 | AI3: 99.622702 | AJ3: 1.992454 | AK3: 6.992454 | AL3: 45268 | AN3: N | AO3: -195
A4: Ritu Bhargava | B4: CX Management America | C4: Schmidt, Marcus <marcus.schmidt@sap.com> | D4: Source Code | E4: On-Premise | F4: P1 | G4: S1 | H4: Y | I4: OneTime Scan | J4: 303250779_UKHD_Data5.0 | L4: 45212 | M4: 45602 | N4: 45306 | O4: GTLC Germany | P4: Rajat | Q4: Done | R4: Y | S4: 45274 | T4: 45281 | AB4: 500000 | AC4: Open | AD4: No | AE4: Yes | AF4: I501689 | AG4: 7.0226427 | AH4: 1.509434 | AI4: 101.13214 | AJ4: 2.0226427 | AK4: 7.0226427 | AL4: 45274 | AN4: N | AO4: 25
A5: Ritu Bhargava | B5: CX Management America | C5: Sundaram, Lakshmi <lakshmi.sundaram@sap.com> | D5: Source Code | E5: On-Premise | F5: P1 | G5: S1 | H5: N | I5: OneTime Scan | J5: 304255988_Nestle_Comm_Cld_17 | L5: 45252 | M5: 45604 | N5: 45322 | O5: GTLC China | P5: Yi Zhang | Q5: Done | R5: Y | S5: 45264 | T5: 45296 | W5: [CTPSAPPRODUCT-4710] 304255988_Nestle_Comm_Cld_17 - SAPJIRA (tools.sap) | Y5: [WEBSERVSAPPRODUCT-3662] 304255988_Nestle_Comm_Cld_17 - SAPJIRA (tools.sap) | AA5: Export scan is assigned to Prashant | AB5: 500001 | AC5: Open | AD5: No | AE5: Yes | AF5: I559269 | AG5: 7.3245301 | AH5: 15.09437 | AI5: 116.22651 | AJ5: 2.3245301 | AK5: 7.3245301 | AL5: 45248 | AN5: N | AO5: 26
A6: Philipp Herzig | B6: Product Engineering Intelligent Enterprise and Cross Architecture | C6: Degac, Jennifer <jennifer.degac@sap.com> | D6: Source Code | E6: On-Premise | F6: P1 | G6: S1 | H6: N | I6: OneTime Scan | J6: 305067921_CSD_Peras_Onboarding_Process_Phase1 | L6: 45345 | M6: 45623 | N6: 45350 | O6: GTLC India | P6: Viswa | Q6: Done | R6: Y | S6: 45350 | T6: 45358 | AA6: CSD | BD Setup | AB6: 500000 | AC6: Open | AD6: No | AE6: Yes | AF6: C5366020 | AG6: 7.6264169 | AH6: 15.09434 | AI6: 131.32085 | AJ6: 2.6264169 | AK6: 7.6264169 | AL6: 45345 | AN6: N | AO6: -8
A7: Claudio Muruzabal | B7: EMEA South, Customer Success | C7: Kumar, Vivek <vivek.kumar11@sap.com>; Kumar, Rahul <rahul03.kumar@sap.com> | D7: Source Code | E7: On-Premise | F7: P1 | G7: S1 | H7: N | I7: Incremental ONLY | J7: 304542393_CSD_DTInboundLogBTPDev | L7: 45331 | M7: 45628 | N7: 45355 | O7: GTLC Germany | P7: Shweta | Q7: Done | R7: Y | S7: 45335 | T7: 45344 | W7: [CTPSAPPRODUCT-4724] 304542393_CSD_DTInboundLogBTPDev - SAPJIRA (tools.sap) | Z7: [WEBSERVSAPPRODUCT-3675] 304542393_CSD_DTInboundLogBTPDev - SAPJIRA (tools.sap) | AB7: 500000 | AC7: Open | AD7: No | AE7: Yes | AF7: D059874 | AG7: 7.9283037 | AH7: 15.09434 | AI7: 146.41518 | AJ7: 2.9283037 | AK7: 7.9283037 | AL7: 45323 | AN7: N | AO7: 11
A8: Claudio Muruzabal | B8: EMEA South, Customer Success | C8: Kumar, Vivek <vivek.kumar11@sap.com> | D8: Source Code | E8: On-Demand (SaaS) | F8: P1 | G8: S1 | H8: N | I8: OneTime Scan | J8: 304639959_CSD_FUJITSU_ORG_CHANGE_V2_FUJITSU | L8: 45345 | M8: 45622 | N8: 45359 | O8: GTLC India | P8: Apoorva | Q8: Done | R8: Y | S8: 45356 | T8: 45358 | AA8: Export Scan required - Chaitanya | Was assigend to Chaitnya on 23/2/24 but no update and OOO. Hence, reassigned | CSD | AB8: 500000 | AC8: Open | AD8: No | AE8: Yes | AF8: C5367590 | AG8: 8.2301905 | AH8: 15.09434 | AI8: 161.50952 | AJ8: 3.2301905 | AK8: 8.2301905 | AL8: 45345 | AN8: N | AO8: 1
A9: Claudio Muruzabal | B9: EMEA South, Customer Success | C9: Sikri, Sanjam <sanjam.sikri@sap.com>; Velumani, Srinivasan <srinivasan.velumani@sap.com> | D9: Source Code | E9: On-Premise | F9: P1 | G9: S1 | H9: N | I9: Incremental ONLY | J9: 304675208_CSD_ASDA_MDK | L9: 45331 | M9: 45622 | N9: 45370 | O9: GTLC China | P9: Yi Zhang | Q9: Done | R9: Y | S9: 45356 | T9: 45359 | W9: [CTPSAPPRODUCT-4725] 304675208_CSD_ASDA_MDK - SAPJIRA (tools.sap) | Z9: [WEBSERVSAPPRODUCT-3676] 304675208_CSD_ASDA_MDK - SAPJIRA (tools.sap) | AB9: 500000 | AC9: Open | AD9: No | AE9: Yes | AF9: I559269 | AG9: 8.5320773 | AH9: 15.09434 | AI9: 176.60386 | AJ9: 3.5320773 | AK9: 8.5320773 | AL9: 45313 | AN9: N | AO9: 11
